<?xml version="1.0"?>
<robot xmlns:xacro="http://www.ros.org/wiki/xacro" >


<xacro:include filename="inertial_macros.xacro"/>


<xacro:include filename="material.xacro"/>
    
  

    <link name="base_link">

    </link>

    <joint name="chassis_joint" type="fixed">
        <parent link="base_link"/>
        <child link="chassis"/>
        <origin xyz="-0.5 0.0 0.0" rpy="0.0 0.0 0.0"/>   
    </joint>

    <link name="chassis">
        <visual>
            <origin xyz="0.5 0.0 0.17" rpy="0.0 0.0 0.0"/>
            <geometry>
                <box size="1 0.5 0.34"/>
            </geometry>
            <material name="gray"/>    
        </visual>
        <collision>
            <origin xyz="0.15 0.0 0.075" rpy="0.0 0.0 0.0"/>
            <geometry>
                <box size="0.3 0.3 0.15"/>
            </geometry>    
        </collision>
        <xacro:inertial_box mass="0.5" x="0.3" y="0.3" z="0.15">
            <origin xyz="0.15 0.0 0.075" rpy="0.0 0.0 0.0"/> 
        </xacro:inertial_box>

    </link>

    <gazebo reference="chassis">
        <material>Gazebo/Wight</material>
    </gazebo>
    

    <joint name="2nd floor" type="fixed">
        <parent link="chassis"/>
        <child link="2nd floor"/>
        <origin xyz="0 0 0.34" rpy="0 0.0 0.0"/>
               
    </joint>


    <link name="2nd floor">
        <visual>
            <origin xyz="0.25 0.0 0.17" rpy="0.0 0.0 0.0"/>
            <geometry>
                <box size="0.5 0.5 0.34"/>
            </geometry>
            <material name="gray"/>    
        </visual>
        <collision>
            <origin xyz="0 0.0 0.0" rpy="0.0 0.0 0.0"/>
            <geometry>
                <box size="1 0.5 0.34"/>
            </geometry>    
        </collision>
        <xacro:inertial_box mass="0.5" x="0.3" y="0.3" z="0.15">
            <origin xyz="0.15 0.0 0.075" rpy="0.0 0.0 0.0"/> 
        </xacro:inertial_box>

    </link>

    <gazebo reference="2nd floor">
        <material>Gazebo/White</material>
    </gazebo>
    


    <joint name="mechanism" type="fixed">
        <parent link="2nd floor"/>
        <child link="mechanism"/>
        <origin xyz="0.5 0 0.0" rpy="0 0.0 0.0"/>
               
    </joint>



    <link name="mechanism">
        <visual>
            <origin xyz="0.25 0.0 0.17" rpy="0.0 0.0 0.0"/>
            <geometry>
                <box size="0.5 0.10 0.34"/>
            </geometry>
            <material name="gray2"/>    
        </visual>
        <collision>
            <origin xyz="0 0.0 0.0" rpy="0.0 0.0 0.0"/>
            <geometry>
                <box size="1 0.5 0.34"/>
            </geometry>    
        </collision>
        <xacro:inertial_box mass="0.5" x="0.3" y="0.3" z="0.15">
            <origin xyz="0.15 0.0 0.075" rpy="0.0 0.0 0.0"/> 
        </xacro:inertial_box>

    </link>

    <gazebo reference="mechanism">
        <material>Gazebo/GreyLight</material>
    </gazebo>
    
    
    <!-- Front left wheel joint -->

    <joint name="FrontLeft_wheel_joint" type="continuous">
        <parent link="base_link"/>
        <child link="FrontLeft_wheel_link"/>
        <origin xyz="0.375 0.29125 0.0" rpy="-${pi/2} 0.0 0.0"/>
        <axis xyz="0.0 0.0 1"/>
    </joint>

    
    
    <link name="FrontLeft_wheel_link">
        <visual>
            <geometry>
                <cylinder radius="0.125" length="0.0825"/>
            </geometry>
            <material name="black" />
        </visual>
        <collision>
            <geometry>
                <cylinder radius="0.125" length="0.165"/>
            </geometry>
        </collision>
        <xacro:inertial_cylinder mass="0.1" length="0.04" radius="0.05">
            <origin xyz="0.0 0.0 0.0" rpy="0.0 0.0 0.0"/> 
        </xacro:inertial_cylinder>
    </link>
    

    <gazebo reference="FrontLeft_wheel_link">
        <material>Gazebo/Black</material>
        <mu1 value="0.0001"/>
        <mu2 value="0.0001"/>
    </gazebo>

<!-- Front Right wheel joint -->

    <joint name="FrontRight_wheel_joint" type="continuous">
        <parent link="base_link"/>
        <child link="FrontRight_wheel_link"/>
        <origin xyz="0.375 -0.29125 0.0" rpy="${pi/2} 0.0 0.0"/>
        <axis xyz="0.0 0.0 -1"/>      
    </joint>

    <link name="FrontRight_wheel_link">
        <visual>
            <geometry>
                <cylinder radius="0.125" length="0.0825"/>
            </geometry>
            <material name="black" />
        </visual>
        <collision>
            <geometry>
                <cylinder radius="0.125" length="0.165"/>
            </geometry>
        </collision>
        <xacro:inertial_cylinder mass="0.1" length="0.04" radius="0.05">
            <origin xyz="0.0 0.0 0.0" rpy="0.0 0.0 0.0"/> 
        </xacro:inertial_cylinder>
    </link>
    <gazebo reference="FrontRight_wheel_link">
        <material>Gazebo/Black</material>
        <mu1 value="0.0001"/>
        <mu2 value="0.0001"/>
    </gazebo>



    <!-- Back left wheel joint -->
    <joint name="left_wheel_joint" type="continuous">
        <parent link="chassis"/>
        <child link="BackLeft_wheel_link"/>
        <origin xyz="0.125 0.29125 0.0" rpy="-${pi/2} 0.0 0.0"/>
        <axis xyz="0.0 0.0 1"/>
    </joint>
    
    <link name="BackLeft_wheel_link">
        <visual>
            <geometry>
                <cylinder radius="0.125" length="0.0825"/>
            </geometry>
            <material name="black" />
        </visual>
        <collision>
            <geometry>
                <cylinder radius="0.125" length="0.165"/>
            </geometry>
        </collision>
        <xacro:inertial_cylinder mass="0.1" length="0.165" radius="0.125">
            <origin xyz="0.0 0.0 0.0" rpy="0.0 0.0 0.0"/> 
        </xacro:inertial_cylinder>
    </link>

  <gazebo reference="BackLeft_wheel_link">
    <material>Gazebo/Black</material>
  </gazebo>
   
 

 <!-- back Right wheel joint -->

 <joint name="right_wheel_joint" type="continuous">
    <parent link="chassis"/>
    <child link="BackRight_wheel_link"/>
    <origin xyz="0.125 -0.29125 0.0" rpy="${pi/2} 0.0 0.0"/>
    <axis xyz="0.0 0.0 -1"/>      
</joint>

<link name="BackRight_wheel_link">
    <visual>
        <geometry>
            <cylinder radius="0.125" length="0.0825"/>
        </geometry>
        <material name="black" />
    </visual>
    <collision>
        <geometry>
            <cylinder radius="0.125" length="0.165"/>
        </geometry>
    </collision>
    <xacro:inertial_cylinder mass="0.1" length="0.04" radius="0.05">
        <origin xyz="0.0 0.0 0.0" rpy="0.0 0.0 0.0"/> 
    </xacro:inertial_cylinder>
</link>

  <gazebo reference="BackRight_wheel_link">
    <material>Gazebo/Black</material>
  </gazebo>
  

</robot>